Internal Server Error: /timeseries/
Traceback (most recent call last):
  File "/home/husse408/.local/lib/python3.10/site-packages/django/core/handlers/exception.py", line 55, in inner
    response = get_response(request)
  File "/home/husse408/.local/lib/python3.10/site-packages/django/core/handlers/base.py", line 197, in _get_response
    response = wrapped_callback(request, *callback_args, **callback_kwargs)
  File "/home/husse408/.local/lib/python3.10/site-packages/django/views/decorators/csrf.py", line 65, in _view_wrapper
    return view_func(request, *args, **kwargs)
  File "/home/husse408/.local/lib/python3.10/site-packages/django/views/generic/base.py", line 104, in view
    return self.dispatch(request, *args, **kwargs)
  File "/home/husse408/.local/lib/python3.10/site-packages/rest_framework/views.py", line 509, in dispatch
    response = self.handle_exception(exc)
  File "/home/husse408/.local/lib/python3.10/site-packages/rest_framework/views.py", line 469, in handle_exception
    self.raise_uncaught_exception(exc)
  File "/home/husse408/.local/lib/python3.10/site-packages/rest_framework/views.py", line 480, in raise_uncaught_exception
    raise exc
  File "/home/husse408/.local/lib/python3.10/site-packages/rest_framework/views.py", line 506, in dispatch
    response = handler(request, *args, **kwargs)
  File "/home/husse408/.local/lib/python3.10/site-packages/rest_framework/decorators.py", line 50, in handler
    return func(*args, **kwargs)
  File "/data/iHARPVFullStack/iHARPV/api/views.py", line 50, in getTimeSeries
    _raster = iHARPExecuterInstance.getRaster(
  File "/data/iHARPScripts/iHARPExecutor.py", line 313, in getRaster
    raise ValueError("iHARPV: Query range or resolution not supported")
ValueError: iHARPV: Query range or resolution not supported
[09/Jun/2024 23:23:47] "POST /timeseries/ HTTP/1.0" 500 110187
/data/iHARPScripts/iHARPExecutor.py changed, reloading.
/data/iHARPVFullStack/iHARPV
Performing system checks...

0.39871640836351874
System check identified no issues (0 silenced).
June 09, 2024 - 23:22:23
Django version 5.0.4, using settings 'BackEnd.settings'
Starting development server at http://0.0.0.0:6080/
Quit the server with CONTROL-C.

Request for Time Seies 
Request for Time Seies 
Request for Time Seies 
Watching for file changes with StatReloader
/data/iHARPScripts/iHARPExecutor.py changed, reloading.
/data/iHARPVFullStack/iHARPV
Performing system checks...

0.5909137598821675
System check identified no issues (0 silenced).
June 09, 2024 - 23:25:24
Django version 5.0.4, using settings 'BackEnd.settings'
Starting development server at http://0.0.0.0:6080/
Quit the server with CONTROL-C.

Request for Time Seies 
Watching for file changes with StatReloader
Internal Server Error: /timeseries/
Traceback (most recent call last):
  File "/home/husse408/.local/lib/python3.10/site-packages/django/core/handlers/exception.py", line 55, in inner
    response = get_response(request)
  File "/home/husse408/.local/lib/python3.10/site-packages/django/core/handlers/base.py", line 197, in _get_response
    response = wrapped_callback(request, *callback_args, **callback_kwargs)
  File "/home/husse408/.local/lib/python3.10/site-packages/django/views/decorators/csrf.py", line 65, in _view_wrapper
    return view_func(request, *args, **kwargs)
  File "/home/husse408/.local/lib/python3.10/site-packages/django/views/generic/base.py", line 104, in view
    return self.dispatch(request, *args, **kwargs)
  File "/home/husse408/.local/lib/python3.10/site-packages/rest_framework/views.py", line 509, in dispatch
    response = self.handle_exception(exc)
  File "/home/husse408/.local/lib/python3.10/site-packages/rest_framework/views.py", line 469, in handle_exception
    self.raise_uncaught_exception(exc)
  File "/home/husse408/.local/lib/python3.10/site-packages/rest_framework/views.py", line 480, in raise_uncaught_exception
    raise exc
  File "/home/husse408/.local/lib/python3.10/site-packages/rest_framework/views.py", line 506, in dispatch
    response = handler(request, *args, **kwargs)
  File "/home/husse408/.local/lib/python3.10/site-packages/rest_framework/decorators.py", line 50, in handler
    return func(*args, **kwargs)
  File "/data/iHARPVFullStack/iHARPV/api/views.py", line 50, in getTimeSeries
    _raster = iHARPExecuterInstance.getRaster(
  File "/data/iHARPScripts/iHARPExecutor.py", line 324, in getRaster
    raise ValueError("iHARPV: Query range or resolution not supported")
ValueError: iHARPV: Query range or resolution not supported
[09/Jun/2024 23:25:39] "POST /timeseries/ HTTP/1.0" 500 110170
/data/iHARPScripts/iHARPExecutor.py changed, reloading.
/data/iHARPVFullStack/iHARPV
Performing system checks...

0.7803677016373358
System check identified no issues (0 silenced).
June 09, 2024 - 23:25:29
Django version 5.0.4, using settings 'BackEnd.settings'
Starting development server at http://0.0.0.0:6080/
Quit the server with CONTROL-C.

Request for Time Seies 
2m temperature 2023-01-01T06 2023-01-01T07 Hourly Maximum 58.0 72.0 -57.0 -11.0 0.25
Watching for file changes with StatReloader
/data/iHARPVFullStack/iHARPV/api/views.py changed, reloading.
/data/iHARPVFullStack/iHARPV
Performing system checks...

0.9046376220580208
System check identified no issues (0 silenced).
June 09, 2024 - 23:26:02
Django version 5.0.4, using settings 'BackEnd.settings'
Starting development server at http://0.0.0.0:6080/
Quit the server with CONTROL-C.

Watching for file changes with StatReloader
/data/iHARPScripts/iHARPExecutor.py changed, reloading.
/data/iHARPVFullStack/iHARPV
Performing system checks...

0.9166011131194988
System check identified no issues (0 silenced).
June 09, 2024 - 23:28:11
Django version 5.0.4, using settings 'BackEnd.settings'
Starting development server at http://0.0.0.0:6080/
Quit the server with CONTROL-C.

Watching for file changes with StatReloader
Internal Server Error: /timeseries/
Traceback (most recent call last):
  File "/home/husse408/.local/lib/python3.10/site-packages/django/core/handlers/exception.py", line 55, in inner
    response = get_response(request)
  File "/home/husse408/.local/lib/python3.10/site-packages/django/core/handlers/base.py", line 197, in _get_response
    response = wrapped_callback(request, *callback_args, **callback_kwargs)
  File "/home/husse408/.local/lib/python3.10/site-packages/django/views/decorators/csrf.py", line 65, in _view_wrapper
    return view_func(request, *args, **kwargs)
  File "/home/husse408/.local/lib/python3.10/site-packages/django/views/generic/base.py", line 104, in view
    return self.dispatch(request, *args, **kwargs)
  File "/home/husse408/.local/lib/python3.10/site-packages/rest_framework/views.py", line 509, in dispatch
    response = self.handle_exception(exc)
  File "/home/husse408/.local/lib/python3.10/site-packages/rest_framework/views.py", line 469, in handle_exception
    self.raise_uncaught_exception(exc)
  File "/home/husse408/.local/lib/python3.10/site-packages/rest_framework/views.py", line 480, in raise_uncaught_exception
    raise exc
  File "/home/husse408/.local/lib/python3.10/site-packages/rest_framework/views.py", line 506, in dispatch
    response = handler(request, *args, **kwargs)
  File "/home/husse408/.local/lib/python3.10/site-packages/rest_framework/decorators.py", line 50, in handler
    return func(*args, **kwargs)
  File "/data/iHARPVFullStack/iHARPV/api/views.py", line 51, in getTimeSeries
    _raster = iHARPExecuterInstance.getRaster(
  File "/data/iHARPScripts/iHARPExecutor.py", line 345, in getRaster
    ds = self.spatialDownsample(ds)
  File "/data/iHARPScripts/iHARPExecutor.py", line 284, in spatialDownsample
    latitude=np.arange(self.max_lat, self.min_lat, -self.spatial_resolution),
TypeError: bad operand type for unary -: 'str'
[09/Jun/2024 23:29:26] "POST /timeseries/ HTTP/1.0" 500 116108
/data/iHARPScripts/iHARPExecutor.py changed, reloading.
/data/iHARPVFullStack/iHARPV
Performing system checks...

0.5006452736481485
System check identified no issues (0 silenced).
June 09, 2024 - 23:29:26
Django version 5.0.4, using settings 'BackEnd.settings'
Starting development server at http://0.0.0.0:6080/
Quit the server with CONTROL-C.

Request for Time Seies 
Hey
tp 2023-01-01T06 2023-01-01T07 hourly maximum 58.0 72.0 -57.0 -11.0 0.25
Watching for file changes with StatReloader
/data/iHARPVFullStack/iHARPV/api/views.py changed, reloading.
/data/iHARPVFullStack/iHARPV
Performing system checks...

0.5522301104544876
System check identified no issues (0 silenced).
June 09, 2024 - 23:30:28
Django version 5.0.4, using settings 'BackEnd.settings'
Starting development server at http://0.0.0.0:6080/
Quit the server with CONTROL-C.

Watching for file changes with StatReloader
[09/Jun/2024 23:30:44] "POST /timeseries/ HTTP/1.0" 201 8595
[09/Jun/2024 23:31:03] "POST /timeseries/ HTTP/1.0" 201 10593
[09/Jun/2024 23:31:32] "POST /timeseries/ HTTP/1.0" 201 31660
Internal Server Error: /areas/
Traceback (most recent call last):
  File "/home/husse408/.local/lib/python3.10/site-packages/pandas/core/indexes/base.py", line 3805, in get_loc
    return self._engine.get_loc(casted_key)
  File "index.pyx", line 167, in pandas._libs.index.IndexEngine.get_loc
  File "index.pyx", line 196, in pandas._libs.index.IndexEngine.get_loc
  File "pandas/_libs/hashtable_class_helper.pxi", line 7081, in pandas._libs.hashtable.PyObjectHashTable.get_item
  File "pandas/_libs/hashtable_class_helper.pxi", line 7089, in pandas._libs.hashtable.PyObjectHashTable.get_item
KeyError: 'sp'

The above exception was the direct cause of the following exception:

Traceback (most recent call last):
  File "/home/husse408/.local/lib/python3.10/site-packages/django/core/handlers/exception.py", line 55, in inner
    response = get_response(request)
  File "/home/husse408/.local/lib/python3.10/site-packages/django/core/handlers/base.py", line 197, in _get_response
    response = wrapped_callback(request, *callback_args, **callback_kwargs)
  File "/home/husse408/.local/lib/python3.10/site-packages/django/views/decorators/csrf.py", line 65, in _view_wrapper
    return view_func(request, *args, **kwargs)
  File "/home/husse408/.local/lib/python3.10/site-packages/django/views/generic/base.py", line 104, in view
    return self.dispatch(request, *args, **kwargs)
  File "/home/husse408/.local/lib/python3.10/site-packages/rest_framework/views.py", line 509, in dispatch
    response = self.handle_exception(exc)
  File "/home/husse408/.local/lib/python3.10/site-packages/rest_framework/views.py", line 469, in handle_exception
    self.raise_uncaught_exception(exc)
  File "/home/husse408/.local/lib/python3.10/site-packages/rest_framework/views.py", line 480, in raise_uncaught_exception
    raise exc
  File "/home/husse408/.local/lib/python3.10/site-packages/rest_framework/views.py", line 506, in dispatch
    response = handler(request, *args, **kwargs)
  File "/home/husse408/.local/lib/python3.10/site-packages/rest_framework/decorators.py", line 50, in handler
    return func(*args, **kwargs)
  File "/data/iHARPVFullStack/iHARPV/api/views.py", line 133, in getAreas
    jsonData = iHARPExecuterInstance.getAreas(
  File "/data/iHARPScripts/iHARPExecutor.py", line 1034, in getAreas
    print("Total number of values in DataFrame:", filtered_df["sp"].size)
  File "/home/husse408/.local/lib/python3.10/site-packages/pandas/core/frame.py", line 4102, in __getitem__
    indexer = self.columns.get_loc(key)
  File "/home/husse408/.local/lib/python3.10/site-packages/pandas/core/indexes/base.py", line 3812, in get_loc
    raise KeyError(key) from err
KeyError: 'sp'
[09/Jun/2024 23:31:46] "POST /areas/ HTTP/1.0" 500 140663
Internal Server Error: /areas/
Traceback (most recent call last):
  File "/home/husse408/.local/lib/python3.10/site-packages/pandas/core/indexes/base.py", line 3805, in get_loc
    return self._engine.get_loc(casted_key)
  File "index.pyx", line 167, in pandas._libs.index.IndexEngine.get_loc
  File "index.pyx", line 196, in pandas._libs.index.IndexEngine.get_loc
  File "pandas/_libs/hashtable_class_helper.pxi", line 7081, in pandas._libs.hashtable.PyObjectHashTable.get_item
  File "pandas/_libs/hashtable_class_helper.pxi", line 7089, in pandas._libs.hashtable.PyObjectHashTable.get_item
KeyError: 'sp'

The above exception was the direct cause of the following exception:

Traceback (most recent call last):
  File "/home/husse408/.local/lib/python3.10/site-packages/django/core/handlers/exception.py", line 55, in inner
    response = get_response(request)
  File "/home/husse408/.local/lib/python3.10/site-packages/django/core/handlers/base.py", line 197, in _get_response
    response = wrapped_callback(request, *callback_args, **callback_kwargs)
  File "/home/husse408/.local/lib/python3.10/site-packages/django/views/decorators/csrf.py", line 65, in _view_wrapper
    return view_func(request, *args, **kwargs)
  File "/home/husse408/.local/lib/python3.10/site-packages/django/views/generic/base.py", line 104, in view
    return self.dispatch(request, *args, **kwargs)
  File "/home/husse408/.local/lib/python3.10/site-packages/rest_framework/views.py", line 509, in dispatch
    response = self.handle_exception(exc)
  File "/home/husse408/.local/lib/python3.10/site-packages/rest_framework/views.py", line 469, in handle_exception
    self.raise_uncaught_exception(exc)
  File "/home/husse408/.local/lib/python3.10/site-packages/rest_framework/views.py", line 480, in raise_uncaught_exception
    raise exc
  File "/home/husse408/.local/lib/python3.10/site-packages/rest_framework/views.py", line 506, in dispatch
    response = handler(request, *args, **kwargs)
  File "/home/husse408/.local/lib/python3.10/site-packages/rest_framework/decorators.py", line 50, in handler
    return func(*args, **kwargs)
  File "/data/iHARPVFullStack/iHARPV/api/views.py", line 133, in getAreas
    jsonData = iHARPExecuterInstance.getAreas(
  File "/data/iHARPScripts/iHARPExecutor.py", line 1034, in getAreas
    print("Total number of values in DataFrame:", filtered_df["sp"].size)
  File "/home/husse408/.local/lib/python3.10/site-packages/pandas/core/frame.py", line 4102, in __getitem__
    indexer = self.columns.get_loc(key)
  File "/home/husse408/.local/lib/python3.10/site-packages/pandas/core/indexes/base.py", line 3812, in get_loc
    raise KeyError(key) from err
KeyError: 'sp'
[09/Jun/2024 23:31:46] "POST /areas/ HTTP/1.0" 500 140663
[09/Jun/2024 23:31:47] "POST /timeseries/ HTTP/1.0" 201 10593
[09/Jun/2024 23:31:57] "POST /timeseries/ HTTP/1.0" 201 10530
Internal Server Error: /timeseries/
Traceback (most recent call last):
  File "/home/husse408/.local/lib/python3.10/site-packages/django/core/handlers/exception.py", line 55, in inner
    response = get_response(request)
  File "/home/husse408/.local/lib/python3.10/site-packages/django/core/handlers/base.py", line 197, in _get_response
    response = wrapped_callback(request, *callback_args, **callback_kwargs)
  File "/home/husse408/.local/lib/python3.10/site-packages/django/views/decorators/csrf.py", line 65, in _view_wrapper
    return view_func(request, *args, **kwargs)
  File "/home/husse408/.local/lib/python3.10/site-packages/django/views/generic/base.py", line 104, in view
    return self.dispatch(request, *args, **kwargs)
  File "/home/husse408/.local/lib/python3.10/site-packages/rest_framework/views.py", line 509, in dispatch
    response = self.handle_exception(exc)
  File "/home/husse408/.local/lib/python3.10/site-packages/rest_framework/views.py", line 469, in handle_exception
    self.raise_uncaught_exception(exc)
  File "/home/husse408/.local/lib/python3.10/site-packages/rest_framework/views.py", line 480, in raise_uncaught_exception
    raise exc
  File "/home/husse408/.local/lib/python3.10/site-packages/rest_framework/views.py", line 506, in dispatch
    response = handler(request, *args, **kwargs)
  File "/home/husse408/.local/lib/python3.10/site-packages/rest_framework/decorators.py", line 50, in handler
    return func(*args, **kwargs)
  File "/data/iHARPVFullStack/iHARPV/api/views.py", line 51, in getTimeSeries
    _raster = iHARPExecuterInstance.getRaster(
  File "/data/iHARPScripts/iHARPExecutor.py", line 331, in getRaster
    raise ValueError("iHARPV: Query range or resolution not supported")
ValueError: iHARPV: Query range or resolution not supported
[09/Jun/2024 23:32:04] "POST /timeseries/ HTTP/1.0" 500 110078
Internal Server Error: /timeseries/
Traceback (most recent call last):
  File "/home/husse408/.local/lib/python3.10/site-packages/xarray/backends/file_manager.py", line 211, in _acquire_with_cache_info
    file = self._cache[self._key]
  File "/home/husse408/.local/lib/python3.10/site-packages/xarray/backends/lru_cache.py", line 56, in __getitem__
    value = self._cache[key]
KeyError: [<class 'netCDF4._netCDF4.Dataset'>, ('/data/era5/preprocessed/t2m/combined_daily_maximum_2014_2023.nc',), 'r', (('clobber', True), ('diskless', False), ('format', 'NETCDF4'), ('persist', False)), '84c4e88e-3329-454a-a91a-fb567bad7d51']

During handling of the above exception, another exception occurred:

Traceback (most recent call last):
  File "/home/husse408/.local/lib/python3.10/site-packages/django/core/handlers/exception.py", line 55, in inner
    response = get_response(request)
  File "/home/husse408/.local/lib/python3.10/site-packages/django/core/handlers/base.py", line 197, in _get_response
    response = wrapped_callback(request, *callback_args, **callback_kwargs)
  File "/home/husse408/.local/lib/python3.10/site-packages/django/views/decorators/csrf.py", line 65, in _view_wrapper
    return view_func(request, *args, **kwargs)
  File "/home/husse408/.local/lib/python3.10/site-packages/django/views/generic/base.py", line 104, in view
    return self.dispatch(request, *args, **kwargs)
  File "/home/husse408/.local/lib/python3.10/site-packages/rest_framework/views.py", line 509, in dispatch
    response = self.handle_exception(exc)
  File "/home/husse408/.local/lib/python3.10/site-packages/rest_framework/views.py", line 469, in handle_exception
    self.raise_uncaught_exception(exc)
  File "/home/husse408/.local/lib/python3.10/site-packages/rest_framework/views.py", line 480, in raise_uncaught_exception
    raise exc
  File "/home/husse408/.local/lib/python3.10/site-packages/rest_framework/views.py", line 506, in dispatch
    response = handler(request, *args, **kwargs)
  File "/home/husse408/.local/lib/python3.10/site-packages/rest_framework/decorators.py", line 50, in handler
    return func(*args, **kwargs)
  File "/data/iHARPVFullStack/iHARPV/api/views.py", line 51, in getTimeSeries
    _raster = iHARPExecuterInstance.getRaster(
  File "/data/iHARPScripts/iHARPExecutor.py", line 336, in getRaster
    ds = xr.open_dataset(file, engine="netcdf4").sel(
  File "/home/husse408/.local/lib/python3.10/site-packages/xarray/backends/api.py", line 573, in open_dataset
    backend_ds = backend.open_dataset(
  File "/home/husse408/.local/lib/python3.10/site-packages/xarray/backends/netCDF4_.py", line 646, in open_dataset
    store = NetCDF4DataStore.open(
  File "/home/husse408/.local/lib/python3.10/site-packages/xarray/backends/netCDF4_.py", line 409, in open
    return cls(manager, group=group, mode=mode, lock=lock, autoclose=autoclose)
  File "/home/husse408/.local/lib/python3.10/site-packages/xarray/backends/netCDF4_.py", line 356, in __init__
    self.format = self.ds.data_model
  File "/home/husse408/.local/lib/python3.10/site-packages/xarray/backends/netCDF4_.py", line 418, in ds
    return self._acquire()
  File "/home/husse408/.local/lib/python3.10/site-packages/xarray/backends/netCDF4_.py", line 412, in _acquire
    with self._manager.acquire_context(needs_lock) as root:
  File "/usr/lib/python3.10/contextlib.py", line 135, in __enter__
    return next(self.gen)
  File "/home/husse408/.local/lib/python3.10/site-packages/xarray/backends/file_manager.py", line 199, in acquire_context
    file, cached = self._acquire_with_cache_info(needs_lock)
  File "/home/husse408/.local/lib/python3.10/site-packages/xarray/backends/file_manager.py", line 217, in _acquire_with_cache_info
    file = self._opener(*self._args, **kwargs)
  File "src/netCDF4/_netCDF4.pyx", line 2469, in netCDF4._netCDF4.Dataset.__init__
  File "src/netCDF4/_netCDF4.pyx", line 2028, in netCDF4._netCDF4._ensure_nc_success
FileNotFoundError: [Errno 2] No such file or directory: '/data/era5/preprocessed/t2m/combined_daily_maximum_2014_2023.nc'
[09/Jun/2024 23:33:01] "POST /timeseries/ HTTP/1.0" 500 166907
Internal Server Error: /timeseries/
Traceback (most recent call last):
  File "/home/husse408/.local/lib/python3.10/site-packages/xarray/backends/file_manager.py", line 211, in _acquire_with_cache_info
    file = self._cache[self._key]
  File "/home/husse408/.local/lib/python3.10/site-packages/xarray/backends/lru_cache.py", line 56, in __getitem__
    value = self._cache[key]
KeyError: [<class 'netCDF4._netCDF4.Dataset'>, ('/data/era5/preprocessed/t2m/combined_daily_maximum_2014_2023.nc',), 'r', (('clobber', True), ('diskless', False), ('format', 'NETCDF4'), ('persist', False)), '03f92814-9165-4943-9818-ef7ba5a42e8c']

During handling of the above exception, another exception occurred:

Traceback (most recent call last):
  File "/home/husse408/.local/lib/python3.10/site-packages/django/core/handlers/exception.py", line 55, in inner
    response = get_response(request)
  File "/home/husse408/.local/lib/python3.10/site-packages/django/core/handlers/base.py", line 197, in _get_response
    response = wrapped_callback(request, *callback_args, **callback_kwargs)
  File "/home/husse408/.local/lib/python3.10/site-packages/django/views/decorators/csrf.py", line 65, in _view_wrapper
    return view_func(request, *args, **kwargs)
  File "/home/husse408/.local/lib/python3.10/site-packages/django/views/generic/base.py", line 104, in view
    return self.dispatch(request, *args, **kwargs)
  File "/home/husse408/.local/lib/python3.10/site-packages/rest_framework/views.py", line 509, in dispatch
    response = self.handle_exception(exc)
  File "/home/husse408/.local/lib/python3.10/site-packages/rest_framework/views.py", line 469, in handle_exception
    self.raise_uncaught_exception(exc)
  File "/home/husse408/.local/lib/python3.10/site-packages/rest_framework/views.py", line 480, in raise_uncaught_exception
    raise exc
  File "/home/husse408/.local/lib/python3.10/site-packages/rest_framework/views.py", line 506, in dispatch
    response = handler(request, *args, **kwargs)
  File "/home/husse408/.local/lib/python3.10/site-packages/rest_framework/decorators.py", line 50, in handler
    return func(*args, **kwargs)
  File "/data/iHARPVFullStack/iHARPV/api/views.py", line 51, in getTimeSeries
    _raster = iHARPExecuterInstance.getRaster(
  File "/data/iHARPScripts/iHARPExecutor.py", line 336, in getRaster
    ds = xr.open_dataset(file, engine="netcdf4").sel(
  File "/home/husse408/.local/lib/python3.10/site-packages/xarray/backends/api.py", line 573, in open_dataset
    backend_ds = backend.open_dataset(
  File "/home/husse408/.local/lib/python3.10/site-packages/xarray/backends/netCDF4_.py", line 646, in open_dataset
    store = NetCDF4DataStore.open(
  File "/home/husse408/.local/lib/python3.10/site-packages/xarray/backends/netCDF4_.py", line 409, in open
    return cls(manager, group=group, mode=mode, lock=lock, autoclose=autoclose)
  File "/home/husse408/.local/lib/python3.10/site-packages/xarray/backends/netCDF4_.py", line 356, in __init__
    self.format = self.ds.data_model
  File "/home/husse408/.local/lib/python3.10/site-packages/xarray/backends/netCDF4_.py", line 418, in ds
    return self._acquire()
  File "/home/husse408/.local/lib/python3.10/site-packages/xarray/backends/netCDF4_.py", line 412, in _acquire
    with self._manager.acquire_context(needs_lock) as root:
  File "/usr/lib/python3.10/contextlib.py", line 135, in __enter__
    return next(self.gen)
  File "/home/husse408/.local/lib/python3.10/site-packages/xarray/backends/file_manager.py", line 199, in acquire_context
    file, cached = self._acquire_with_cache_info(needs_lock)
  File "/home/husse408/.local/lib/python3.10/site-packages/xarray/backends/file_manager.py", line 217, in _acquire_with_cache_info
    file = self._opener(*self._args, **kwargs)
  File "src/netCDF4/_netCDF4.pyx", line 2469, in netCDF4._netCDF4.Dataset.__init__
  File "src/netCDF4/_netCDF4.pyx", line 2028, in netCDF4._netCDF4._ensure_nc_success
FileNotFoundError: [Errno 2] No such file or directory: '/data/era5/preprocessed/t2m/combined_daily_maximum_2014_2023.nc'
[09/Jun/2024 23:33:03] "POST /timeseries/ HTTP/1.0" 500 166907
/data/iHARPVFullStack/iHARPV/api/models.py changed, reloading.
/data/iHARPVFullStack/iHARPV
Performing system checks...

0.17164427919491942
System check identified no issues (0 silenced).
June 09, 2024 - 23:30:39
Django version 5.0.4, using settings 'BackEnd.settings'
Starting development server at http://0.0.0.0:6080/
Quit the server with CONTROL-C.

Request for Time Seies 
Hey
tp 2023-01-01T06 2023-01-01T07 hourly maximum 58.0 72.0 -57.0 -11.0 0.25
Request for Time Seies 
Hey
tp 2023-01-01T06 2023-01-01T23 hourly maximum 58.0 72.0 -57.0 -11.0 0.25
Request for Time Seies 
Hey
tp 2023-01-01T06 2023-01-08T23 hourly maximum 58.0 72.0 -57.0 -11.0 0.25
Request for Areas
Total number of values: 2898
                 time  latitude  longitude        tp  condition_met
0 2023-01-01 06:00:00    71.125    -56.125  0.000048          False
1 2023-01-01 06:00:00    71.125    -54.125  0.000075          False
2 2023-01-01 06:00:00    71.125    -52.125  0.000046          False
3 2023-01-01 06:00:00    71.125    -50.125  0.000005          False
4 2023-01-01 06:00:00    71.125    -48.125  0.000000          False
Request for Areas
Total number of values: 2898
                 time  latitude  longitude        tp  condition_met
0 2023-01-01 06:00:00    71.125    -56.125  0.000048          False
1 2023-01-01 06:00:00    71.125    -54.125  0.000075          False
2 2023-01-01 06:00:00    71.125    -52.125  0.000046          False
3 2023-01-01 06:00:00    71.125    -50.125  0.000005          False
4 2023-01-01 06:00:00    71.125    -48.125  0.000000          False
Request for Time Seies 
Hey
tp 2023-01-01T06 2023-01-01T23 hourly maximum 58.0 72.0 -57.0 -11.0 0.25
Request for Time Seies 
Hey
t2m 2023-01-01T06 2023-01-01T23 hourly maximum 58.0 72.0 -57.0 -11.0 0.25
Request for Time Seies 
Hey
sp 2023-01-01T06 2023-01-01T23 hourly maximum 58.0 72.0 -57.0 -11.0 0.25
Request for Time Seies 
Hey
t2m 2023-01-01T06 2023-01-10T23 daily maximum -70.378 -29.535 -77.344 41.484 0.25
Request for Time Seies 
Hey
t2m 2023-01-01T06 2023-01-10T23 daily maximum -70.378 -29.535 -77.344 41.484 0.25
Watching for file changes with StatReloader
/data/iHARPScripts/iHARPExecutor.py changed, reloading.
/data/iHARPVFullStack/iHARPV
Performing system checks...

0.6055547995449954
System check identified no issues (0 silenced).
June 09, 2024 - 23:34:13
Django version 5.0.4, using settings 'BackEnd.settings'
Starting development server at http://0.0.0.0:6080/
Quit the server with CONTROL-C.

Watching for file changes with StatReloader
System check identified some issues:

WARNINGS:
?: (staticfiles.W004) The directory '/data/iHARPVFullStack/iHARPV/FrontEnd/build/static' in the STATICFILES_DIRS setting does not exist.

System check identified 1 issue (0 silenced).
/data/iHARPScripts/iHARPExecutor.py changed, reloading.
/data/iHARPVFullStack/iHARPV
Performing system checks...

0.09221220057449953
June 09, 2024 - 23:38:01
Django version 5.0.4, using settings 'BackEnd.settings'
Starting development server at http://0.0.0.0:6080/
Quit the server with CONTROL-C.

Watching for file changes with StatReloader
[09/Jun/2024 23:38:40] "GET / HTTP/1.0" 200 546
[09/Jun/2024 23:38:40] "GET /static/css/main.5ffb34c9.css HTTP/1.0" 200 269349
[09/Jun/2024 23:38:40] "GET /static/js/main.a5aa64f3.js HTTP/1.0" 200 5138575
[09/Jun/2024 23:38:41] "GET /static/media/spritesheet.a4e0eb7ad904a4858361.svg HTTP/1.0" 200 5551
[09/Jun/2024 23:38:41] "GET /static/media/heatmapVideo.b408471cc10f46dab99c.mp4 HTTP/1.0" 200 62793
[09/Jun/2024 23:38:49] "POST /timeseries/ HTTP/1.0" 201 8580
[09/Jun/2024 23:38:56] "POST /timeseries/ HTTP/1.0" 201 10522
[09/Jun/2024 23:39:16] "POST /timeseries/ HTTP/1.0" 201 11250
[09/Jun/2024 23:39:28] "POST /timeseries/ HTTP/1.0" 201 8431
[09/Jun/2024 23:39:33] "POST /timeseries/ HTTP/1.0" 201 9258
[09/Jun/2024 23:39:39] "POST /timeseries/ HTTP/1.0" 201 10234
[09/Jun/2024 23:39:59] "POST /timeseries/ HTTP/1.0" 201 10230
/data/iHARPScripts/iHARPExecutor.py changed, reloading.
/data/iHARPVFullStack/iHARPV
Performing system checks...

0.4247205680607349
System check identified no issues (0 silenced).
June 09, 2024 - 23:38:39
Django version 5.0.4, using settings 'BackEnd.settings'
Starting development server at http://0.0.0.0:6080/
Quit the server with CONTROL-C.

Request for Time Seies 
Hey
t2m 2023-01-01T06 2023-01-01T07 hourly max 58.0 72.0 -57.0 -11.0 0.25
Request for Time Seies 
Hey
t2m 2023-01-01T06 2023-01-01T23 hourly max 58.0 72.0 -57.0 -11.0 0.25
Request for Time Seies 
Hey
t2m 2023-01-01T00 2023-01-01T23 hourly max 58.0 72.0 -57.0 -11.0 0.25
Request for Time Seies 
Hey
t2m 2023-01-01T00 2023-01-01T23 daily max 58.0 72.0 -57.0 -11.0 0.25
Request for Time Seies 
Hey
t2m 2023-01-01T00 2023-01-10T23 daily max 58.0 72.0 -57.0 -11.0 0.25
Request for Time Seies 
Hey
t2m 2023-01-01T00 2023-01-20T23 daily max 58.0 72.0 -57.0 -11.0 0.25
Request for Time Seies 
Hey
t2m 2023-01-01T00 2023-01-20T23 daily mean 58.0 72.0 -57.0 -11.0 0.25
Watching for file changes with StatReloader
[09/Jun/2024 23:41:04] "POST /timeseries/ HTTP/1.0" 201 10230
[09/Jun/2024 23:42:42] "POST /timeseries/ HTTP/1.0" 201 10230
/data/iHARPVFullStack/iHARPV
